{
 "cells": [
  {
   "cell_type": "code",
   "execution_count": 3,
   "metadata": {},
   "outputs": [],
   "source": [
    "import tensorflow as tf\n",
    "import numpy as np\n",
    "import pandas as pd\n",
    "import matplotlib.pyplot as plt"
   ]
  },
  {
   "cell_type": "code",
   "execution_count": 6,
   "metadata": {},
   "outputs": [],
   "source": [
    "mnist=tf.keras.datasets.fashion_mnist\n",
    "(X_train,y_train),(X_test,y_test)=mnist.load_data()"
   ]
  },
  {
   "cell_type": "code",
   "execution_count": 7,
   "metadata": {},
   "outputs": [],
   "source": [
    "input_shape=(28,28,1)\n",
    "X_train=X_train.reshape(len(X_train),28,28,1)\n",
    "X_test=X_test.reshape(len(X_test),28,28,1)\n",
    "X_train=X_train/255\n",
    "X_test=X_test/255"
   ]
  },
  {
   "cell_type": "code",
   "execution_count": 8,
   "metadata": {},
   "outputs": [],
   "source": [
    "y_train=tf.one_hot(y_train.astype(np.int32),depth=10)\n",
    "y_test=tf.one_hot(y_test.astype(np.int32),depth=10)"
   ]
  },
  {
   "cell_type": "code",
   "execution_count": 9,
   "metadata": {},
   "outputs": [],
   "source": [
    "batch_size=32\n",
    "epochs=5\n",
    "cnn=tf.keras.models.Sequential()"
   ]
  },
  {
   "cell_type": "code",
   "execution_count": 11,
   "metadata": {},
   "outputs": [
    {
     "name": "stderr",
     "output_type": "stream",
     "text": [
      "C:\\Users\\gobi2\\AppData\\Roaming\\Python\\Python311\\site-packages\\keras\\src\\layers\\convolutional\\base_conv.py:107: UserWarning: Do not pass an `input_shape`/`input_dim` argument to a layer. When using Sequential models, prefer using an `Input(shape)` object as the first layer in the model instead.\n",
      "  super().__init__(activity_regularizer=activity_regularizer, **kwargs)\n"
     ]
    }
   ],
   "source": [
    "cnn.add(tf.keras.layers.Conv2D(filters=32,kernel_size=3,strides=2,padding='same',activation='relu',input_shape=input_shape))"
   ]
  },
  {
   "cell_type": "code",
   "execution_count": 12,
   "metadata": {},
   "outputs": [],
   "source": [
    "cnn.add(tf.keras.layers.Conv2D(filters=32,kernel_size=3,padding='same',activation='relu'))\n",
    "cnn.add(tf.keras.layers.MaxPool2D(pool_size=2,strides=2))\n",
    "cnn.add(tf.keras.layers.Dropout(0.25))"
   ]
  },
  {
   "cell_type": "code",
   "execution_count": 13,
   "metadata": {},
   "outputs": [],
   "source": [
    "cnn.add(tf.keras.layers.Conv2D(filters=32,kernel_size=3,padding='same',activation='relu'))\n",
    "cnn.add(tf.keras.layers.MaxPool2D(pool_size=2,strides=2))\n",
    "cnn.add(tf.keras.layers.Dropout(0.25))"
   ]
  },
  {
   "cell_type": "code",
   "execution_count": 17,
   "metadata": {},
   "outputs": [],
   "source": [
    "cnn.add(tf.keras.layers.Flatten())\n",
    "cnn.add(tf.keras.layers.Dense(units=128,activation='relu'))\n",
    "cnn.add(tf.keras.layers.Dense(units=10,activation='softmax'))"
   ]
  },
  {
   "cell_type": "code",
   "execution_count": 18,
   "metadata": {},
   "outputs": [],
   "source": [
    "cnn.compile(optimizer='adam',loss='categorical_crossentropy',metrics=['acc'])"
   ]
  },
  {
   "cell_type": "code",
   "execution_count": 19,
   "metadata": {},
   "outputs": [
    {
     "name": "stdout",
     "output_type": "stream",
     "text": [
      "Epoch 1/5\n"
     ]
    },
    {
     "ename": "InvalidArgumentError",
     "evalue": "Graph execution error:\n\nDetected at node sequential_1/conv2d_1_2/Reshape defined at (most recent call last):\n  File \"<frozen runpy>\", line 198, in _run_module_as_main\n\n  File \"<frozen runpy>\", line 88, in _run_code\n\n  File \"c:\\ProgramData\\anaconda3\\Lib\\site-packages\\ipykernel_launcher.py\", line 17, in <module>\n\n  File \"c:\\ProgramData\\anaconda3\\Lib\\site-packages\\traitlets\\config\\application.py\", line 992, in launch_instance\n\n  File \"c:\\ProgramData\\anaconda3\\Lib\\site-packages\\ipykernel\\kernelapp.py\", line 701, in start\n\n  File \"c:\\ProgramData\\anaconda3\\Lib\\site-packages\\tornado\\platform\\asyncio.py\", line 195, in start\n\n  File \"c:\\ProgramData\\anaconda3\\Lib\\asyncio\\windows_events.py\", line 321, in run_forever\n\n  File \"c:\\ProgramData\\anaconda3\\Lib\\asyncio\\base_events.py\", line 607, in run_forever\n\n  File \"c:\\ProgramData\\anaconda3\\Lib\\asyncio\\base_events.py\", line 1922, in _run_once\n\n  File \"c:\\ProgramData\\anaconda3\\Lib\\asyncio\\events.py\", line 80, in _run\n\n  File \"c:\\ProgramData\\anaconda3\\Lib\\site-packages\\ipykernel\\kernelbase.py\", line 534, in dispatch_queue\n\n  File \"c:\\ProgramData\\anaconda3\\Lib\\site-packages\\ipykernel\\kernelbase.py\", line 523, in process_one\n\n  File \"c:\\ProgramData\\anaconda3\\Lib\\site-packages\\ipykernel\\kernelbase.py\", line 429, in dispatch_shell\n\n  File \"c:\\ProgramData\\anaconda3\\Lib\\site-packages\\ipykernel\\kernelbase.py\", line 767, in execute_request\n\n  File \"c:\\ProgramData\\anaconda3\\Lib\\site-packages\\ipykernel\\ipkernel.py\", line 429, in do_execute\n\n  File \"c:\\ProgramData\\anaconda3\\Lib\\site-packages\\ipykernel\\zmqshell.py\", line 549, in run_cell\n\n  File \"c:\\ProgramData\\anaconda3\\Lib\\site-packages\\IPython\\core\\interactiveshell.py\", line 3051, in run_cell\n\n  File \"c:\\ProgramData\\anaconda3\\Lib\\site-packages\\IPython\\core\\interactiveshell.py\", line 3106, in _run_cell\n\n  File \"c:\\ProgramData\\anaconda3\\Lib\\site-packages\\IPython\\core\\async_helpers.py\", line 129, in _pseudo_sync_runner\n\n  File \"c:\\ProgramData\\anaconda3\\Lib\\site-packages\\IPython\\core\\interactiveshell.py\", line 3311, in run_cell_async\n\n  File \"c:\\ProgramData\\anaconda3\\Lib\\site-packages\\IPython\\core\\interactiveshell.py\", line 3493, in run_ast_nodes\n\n  File \"c:\\ProgramData\\anaconda3\\Lib\\site-packages\\IPython\\core\\interactiveshell.py\", line 3553, in run_code\n\n  File \"C:\\Users\\gobi2\\AppData\\Local\\Temp\\ipykernel_15560\\2380388858.py\", line 1, in <module>\n\n  File \"C:\\Users\\gobi2\\AppData\\Roaming\\Python\\Python311\\site-packages\\keras\\src\\utils\\traceback_utils.py\", line 117, in error_handler\n\n  File \"C:\\Users\\gobi2\\AppData\\Roaming\\Python\\Python311\\site-packages\\keras\\src\\backend\\tensorflow\\trainer.py\", line 318, in fit\n\n  File \"C:\\Users\\gobi2\\AppData\\Roaming\\Python\\Python311\\site-packages\\keras\\src\\backend\\tensorflow\\trainer.py\", line 121, in one_step_on_iterator\n\n  File \"C:\\Users\\gobi2\\AppData\\Roaming\\Python\\Python311\\site-packages\\keras\\src\\backend\\tensorflow\\trainer.py\", line 108, in one_step_on_data\n\n  File \"C:\\Users\\gobi2\\AppData\\Roaming\\Python\\Python311\\site-packages\\keras\\src\\backend\\tensorflow\\trainer.py\", line 51, in train_step\n\n  File \"C:\\Users\\gobi2\\AppData\\Roaming\\Python\\Python311\\site-packages\\keras\\src\\utils\\traceback_utils.py\", line 117, in error_handler\n\n  File \"C:\\Users\\gobi2\\AppData\\Roaming\\Python\\Python311\\site-packages\\keras\\src\\layers\\layer.py\", line 882, in __call__\n\n  File \"C:\\Users\\gobi2\\AppData\\Roaming\\Python\\Python311\\site-packages\\keras\\src\\utils\\traceback_utils.py\", line 117, in error_handler\n\n  File \"C:\\Users\\gobi2\\AppData\\Roaming\\Python\\Python311\\site-packages\\keras\\src\\ops\\operation.py\", line 46, in __call__\n\n  File \"C:\\Users\\gobi2\\AppData\\Roaming\\Python\\Python311\\site-packages\\keras\\src\\utils\\traceback_utils.py\", line 156, in error_handler\n\n  File \"C:\\Users\\gobi2\\AppData\\Roaming\\Python\\Python311\\site-packages\\keras\\src\\models\\sequential.py\", line 209, in call\n\n  File \"C:\\Users\\gobi2\\AppData\\Roaming\\Python\\Python311\\site-packages\\keras\\src\\models\\functional.py\", line 175, in call\n\n  File \"C:\\Users\\gobi2\\AppData\\Roaming\\Python\\Python311\\site-packages\\keras\\src\\ops\\function.py\", line 171, in _run_through_graph\n\n  File \"C:\\Users\\gobi2\\AppData\\Roaming\\Python\\Python311\\site-packages\\keras\\src\\models\\functional.py\", line 556, in call\n\n  File \"C:\\Users\\gobi2\\AppData\\Roaming\\Python\\Python311\\site-packages\\keras\\src\\utils\\traceback_utils.py\", line 117, in error_handler\n\n  File \"C:\\Users\\gobi2\\AppData\\Roaming\\Python\\Python311\\site-packages\\keras\\src\\layers\\layer.py\", line 882, in __call__\n\n  File \"C:\\Users\\gobi2\\AppData\\Roaming\\Python\\Python311\\site-packages\\keras\\src\\utils\\traceback_utils.py\", line 117, in error_handler\n\n  File \"C:\\Users\\gobi2\\AppData\\Roaming\\Python\\Python311\\site-packages\\keras\\src\\ops\\operation.py\", line 46, in __call__\n\n  File \"C:\\Users\\gobi2\\AppData\\Roaming\\Python\\Python311\\site-packages\\keras\\src\\utils\\traceback_utils.py\", line 156, in error_handler\n\n  File \"C:\\Users\\gobi2\\AppData\\Roaming\\Python\\Python311\\site-packages\\keras\\src\\layers\\convolutional\\base_conv.py\", line 252, in call\n\n  File \"C:\\Users\\gobi2\\AppData\\Roaming\\Python\\Python311\\site-packages\\keras\\src\\ops\\numpy.py\", line 4440, in reshape\n\n  File \"C:\\Users\\gobi2\\AppData\\Roaming\\Python\\Python311\\site-packages\\keras\\src\\backend\\tensorflow\\numpy.py\", line 1789, in reshape\n\nInput to reshape is a tensor with 0 values, but the requested shape has 32\n\t [[{{node sequential_1/conv2d_1_2/Reshape}}]] [Op:__inference_one_step_on_iterator_3637]",
     "output_type": "error",
     "traceback": [
      "\u001b[1;31m---------------------------------------------------------------------------\u001b[0m",
      "\u001b[1;31mInvalidArgumentError\u001b[0m                      Traceback (most recent call last)",
      "Cell \u001b[1;32mIn[19], line 1\u001b[0m\n\u001b[1;32m----> 1\u001b[0m cnn\u001b[38;5;241m.\u001b[39mfit(X_train,y_train,batch_size\u001b[38;5;241m=\u001b[39mbatch_size,epochs\u001b[38;5;241m=\u001b[39mepochs,validation_split\u001b[38;5;241m=\u001b[39m\u001b[38;5;241m0.1\u001b[39m)\n",
      "File \u001b[1;32m~\\AppData\\Roaming\\Python\\Python311\\site-packages\\keras\\src\\utils\\traceback_utils.py:122\u001b[0m, in \u001b[0;36mfilter_traceback.<locals>.error_handler\u001b[1;34m(*args, **kwargs)\u001b[0m\n\u001b[0;32m    119\u001b[0m     filtered_tb \u001b[38;5;241m=\u001b[39m _process_traceback_frames(e\u001b[38;5;241m.\u001b[39m__traceback__)\n\u001b[0;32m    120\u001b[0m     \u001b[38;5;66;03m# To get the full stack trace, call:\u001b[39;00m\n\u001b[0;32m    121\u001b[0m     \u001b[38;5;66;03m# `keras.config.disable_traceback_filtering()`\u001b[39;00m\n\u001b[1;32m--> 122\u001b[0m     \u001b[38;5;28;01mraise\u001b[39;00m e\u001b[38;5;241m.\u001b[39mwith_traceback(filtered_tb) \u001b[38;5;28;01mfrom\u001b[39;00m \u001b[38;5;28;01mNone\u001b[39;00m\n\u001b[0;32m    123\u001b[0m \u001b[38;5;28;01mfinally\u001b[39;00m:\n\u001b[0;32m    124\u001b[0m     \u001b[38;5;28;01mdel\u001b[39;00m filtered_tb\n",
      "File \u001b[1;32m~\\AppData\\Roaming\\Python\\Python311\\site-packages\\tensorflow\\python\\eager\\execute.py:53\u001b[0m, in \u001b[0;36mquick_execute\u001b[1;34m(op_name, num_outputs, inputs, attrs, ctx, name)\u001b[0m\n\u001b[0;32m     51\u001b[0m \u001b[38;5;28;01mtry\u001b[39;00m:\n\u001b[0;32m     52\u001b[0m   ctx\u001b[38;5;241m.\u001b[39mensure_initialized()\n\u001b[1;32m---> 53\u001b[0m   tensors \u001b[38;5;241m=\u001b[39m pywrap_tfe\u001b[38;5;241m.\u001b[39mTFE_Py_Execute(ctx\u001b[38;5;241m.\u001b[39m_handle, device_name, op_name,\n\u001b[0;32m     54\u001b[0m                                       inputs, attrs, num_outputs)\n\u001b[0;32m     55\u001b[0m \u001b[38;5;28;01mexcept\u001b[39;00m core\u001b[38;5;241m.\u001b[39m_NotOkStatusException \u001b[38;5;28;01mas\u001b[39;00m e:\n\u001b[0;32m     56\u001b[0m   \u001b[38;5;28;01mif\u001b[39;00m name \u001b[38;5;129;01mis\u001b[39;00m \u001b[38;5;129;01mnot\u001b[39;00m \u001b[38;5;28;01mNone\u001b[39;00m:\n",
      "\u001b[1;31mInvalidArgumentError\u001b[0m: Graph execution error:\n\nDetected at node sequential_1/conv2d_1_2/Reshape defined at (most recent call last):\n  File \"<frozen runpy>\", line 198, in _run_module_as_main\n\n  File \"<frozen runpy>\", line 88, in _run_code\n\n  File \"c:\\ProgramData\\anaconda3\\Lib\\site-packages\\ipykernel_launcher.py\", line 17, in <module>\n\n  File \"c:\\ProgramData\\anaconda3\\Lib\\site-packages\\traitlets\\config\\application.py\", line 992, in launch_instance\n\n  File \"c:\\ProgramData\\anaconda3\\Lib\\site-packages\\ipykernel\\kernelapp.py\", line 701, in start\n\n  File \"c:\\ProgramData\\anaconda3\\Lib\\site-packages\\tornado\\platform\\asyncio.py\", line 195, in start\n\n  File \"c:\\ProgramData\\anaconda3\\Lib\\asyncio\\windows_events.py\", line 321, in run_forever\n\n  File \"c:\\ProgramData\\anaconda3\\Lib\\asyncio\\base_events.py\", line 607, in run_forever\n\n  File \"c:\\ProgramData\\anaconda3\\Lib\\asyncio\\base_events.py\", line 1922, in _run_once\n\n  File \"c:\\ProgramData\\anaconda3\\Lib\\asyncio\\events.py\", line 80, in _run\n\n  File \"c:\\ProgramData\\anaconda3\\Lib\\site-packages\\ipykernel\\kernelbase.py\", line 534, in dispatch_queue\n\n  File \"c:\\ProgramData\\anaconda3\\Lib\\site-packages\\ipykernel\\kernelbase.py\", line 523, in process_one\n\n  File \"c:\\ProgramData\\anaconda3\\Lib\\site-packages\\ipykernel\\kernelbase.py\", line 429, in dispatch_shell\n\n  File \"c:\\ProgramData\\anaconda3\\Lib\\site-packages\\ipykernel\\kernelbase.py\", line 767, in execute_request\n\n  File \"c:\\ProgramData\\anaconda3\\Lib\\site-packages\\ipykernel\\ipkernel.py\", line 429, in do_execute\n\n  File \"c:\\ProgramData\\anaconda3\\Lib\\site-packages\\ipykernel\\zmqshell.py\", line 549, in run_cell\n\n  File \"c:\\ProgramData\\anaconda3\\Lib\\site-packages\\IPython\\core\\interactiveshell.py\", line 3051, in run_cell\n\n  File \"c:\\ProgramData\\anaconda3\\Lib\\site-packages\\IPython\\core\\interactiveshell.py\", line 3106, in _run_cell\n\n  File \"c:\\ProgramData\\anaconda3\\Lib\\site-packages\\IPython\\core\\async_helpers.py\", line 129, in _pseudo_sync_runner\n\n  File \"c:\\ProgramData\\anaconda3\\Lib\\site-packages\\IPython\\core\\interactiveshell.py\", line 3311, in run_cell_async\n\n  File \"c:\\ProgramData\\anaconda3\\Lib\\site-packages\\IPython\\core\\interactiveshell.py\", line 3493, in run_ast_nodes\n\n  File \"c:\\ProgramData\\anaconda3\\Lib\\site-packages\\IPython\\core\\interactiveshell.py\", line 3553, in run_code\n\n  File \"C:\\Users\\gobi2\\AppData\\Local\\Temp\\ipykernel_15560\\2380388858.py\", line 1, in <module>\n\n  File \"C:\\Users\\gobi2\\AppData\\Roaming\\Python\\Python311\\site-packages\\keras\\src\\utils\\traceback_utils.py\", line 117, in error_handler\n\n  File \"C:\\Users\\gobi2\\AppData\\Roaming\\Python\\Python311\\site-packages\\keras\\src\\backend\\tensorflow\\trainer.py\", line 318, in fit\n\n  File \"C:\\Users\\gobi2\\AppData\\Roaming\\Python\\Python311\\site-packages\\keras\\src\\backend\\tensorflow\\trainer.py\", line 121, in one_step_on_iterator\n\n  File \"C:\\Users\\gobi2\\AppData\\Roaming\\Python\\Python311\\site-packages\\keras\\src\\backend\\tensorflow\\trainer.py\", line 108, in one_step_on_data\n\n  File \"C:\\Users\\gobi2\\AppData\\Roaming\\Python\\Python311\\site-packages\\keras\\src\\backend\\tensorflow\\trainer.py\", line 51, in train_step\n\n  File \"C:\\Users\\gobi2\\AppData\\Roaming\\Python\\Python311\\site-packages\\keras\\src\\utils\\traceback_utils.py\", line 117, in error_handler\n\n  File \"C:\\Users\\gobi2\\AppData\\Roaming\\Python\\Python311\\site-packages\\keras\\src\\layers\\layer.py\", line 882, in __call__\n\n  File \"C:\\Users\\gobi2\\AppData\\Roaming\\Python\\Python311\\site-packages\\keras\\src\\utils\\traceback_utils.py\", line 117, in error_handler\n\n  File \"C:\\Users\\gobi2\\AppData\\Roaming\\Python\\Python311\\site-packages\\keras\\src\\ops\\operation.py\", line 46, in __call__\n\n  File \"C:\\Users\\gobi2\\AppData\\Roaming\\Python\\Python311\\site-packages\\keras\\src\\utils\\traceback_utils.py\", line 156, in error_handler\n\n  File \"C:\\Users\\gobi2\\AppData\\Roaming\\Python\\Python311\\site-packages\\keras\\src\\models\\sequential.py\", line 209, in call\n\n  File \"C:\\Users\\gobi2\\AppData\\Roaming\\Python\\Python311\\site-packages\\keras\\src\\models\\functional.py\", line 175, in call\n\n  File \"C:\\Users\\gobi2\\AppData\\Roaming\\Python\\Python311\\site-packages\\keras\\src\\ops\\function.py\", line 171, in _run_through_graph\n\n  File \"C:\\Users\\gobi2\\AppData\\Roaming\\Python\\Python311\\site-packages\\keras\\src\\models\\functional.py\", line 556, in call\n\n  File \"C:\\Users\\gobi2\\AppData\\Roaming\\Python\\Python311\\site-packages\\keras\\src\\utils\\traceback_utils.py\", line 117, in error_handler\n\n  File \"C:\\Users\\gobi2\\AppData\\Roaming\\Python\\Python311\\site-packages\\keras\\src\\layers\\layer.py\", line 882, in __call__\n\n  File \"C:\\Users\\gobi2\\AppData\\Roaming\\Python\\Python311\\site-packages\\keras\\src\\utils\\traceback_utils.py\", line 117, in error_handler\n\n  File \"C:\\Users\\gobi2\\AppData\\Roaming\\Python\\Python311\\site-packages\\keras\\src\\ops\\operation.py\", line 46, in __call__\n\n  File \"C:\\Users\\gobi2\\AppData\\Roaming\\Python\\Python311\\site-packages\\keras\\src\\utils\\traceback_utils.py\", line 156, in error_handler\n\n  File \"C:\\Users\\gobi2\\AppData\\Roaming\\Python\\Python311\\site-packages\\keras\\src\\layers\\convolutional\\base_conv.py\", line 252, in call\n\n  File \"C:\\Users\\gobi2\\AppData\\Roaming\\Python\\Python311\\site-packages\\keras\\src\\ops\\numpy.py\", line 4440, in reshape\n\n  File \"C:\\Users\\gobi2\\AppData\\Roaming\\Python\\Python311\\site-packages\\keras\\src\\backend\\tensorflow\\numpy.py\", line 1789, in reshape\n\nInput to reshape is a tensor with 0 values, but the requested shape has 32\n\t [[{{node sequential_1/conv2d_1_2/Reshape}}]] [Op:__inference_one_step_on_iterator_3637]"
     ]
    }
   ],
   "source": [
    "cnn.fit(X_train,y_train,batch_size=batch_size,epochs=epochs,validation_split=0.1)"
   ]
  }
 ],
 "metadata": {
  "kernelspec": {
   "display_name": "base",
   "language": "python",
   "name": "python3"
  },
  "language_info": {
   "codemirror_mode": {
    "name": "ipython",
    "version": 3
   },
   "file_extension": ".py",
   "mimetype": "text/x-python",
   "name": "python",
   "nbconvert_exporter": "python",
   "pygments_lexer": "ipython3",
   "version": "3.11.7"
  }
 },
 "nbformat": 4,
 "nbformat_minor": 2
}
